Workbook
Name UPDATE: 'Data Sheet'!$E$1

Sheet Data Sheet
A1: COMPANY NAME | B1: HINDUSTAN UNILEVER LTD | E1: =IF(B2<>B3, "A NEW VERSION OF THE WORKSHEET IS AVAILABLE", "")
A2: LATEST VERSION | B2: 2.1 | E2: PLEASE DO NOT MAKE ANY CHANGES TO THIS SHEET
A3: CURRENT VERSION | B3: 2.1
A5: META
A6: Number of shares | B6: =IF(B9>0, B9/B8, 0) -> 234.9591
A7: Face Value | B7: 1
A8: Current Price | B8: 1826.3
A9: Market Capitalization | B9: 429105.81
A15: PROFIT & LOSS
A16: Report Date | B16: 42825 | C16: 43190 | D16: 43555 | E16: 43921 | F16: 44286 | G16: 44651 | H16: 45016 | I16: 45382 | J16: 45747 | K16: 46112
A17: Sales | B17: 31890 | C17: 34525 | D17: 38224 | E17: 38785 | F17: 45996 | G17: 51193 | H17: 59144 | I17: 60469 | J17: 59676 | K17: 61975
A18: Raw Material Cost | B18: 13165 | C18: 13859 | D18: 15430 | E18: 15378 | F18: 19784 | G18: 22398 | H18: 28042 | I18: 26598 | J18: 26445 | K18: 28883
A19: Change in Inventory | B19: -156 | C19: 71 | D19: -12 | E19: 121 | F19: 391 | G19: 19 | H19: 53 | I19: 8 | J19: 78 | K19: 395
A20: Power and Fuel | B20: 257 | C20: 259 | D20: 269 | E20: 263 | F20: 304 | G20: 277 | H20: 325 | I20: 384 | J20: 341 | K20: 364
A21: Other Mfr. Exp | B21: 2771 | C21: 2958 | D21: 3018 | E21: 2860 | F21: 2847 | G21: 3329 | H21: 3705 | I21: 3293 | J21: 3508 | K21: 3079
A22: Employee Cost | B22: 1620 | C22: 1745 | D22: 1747 | E22: 1691 | F22: 2229 | G22: 2399 | H22: 2665 | I22: 2782 | J22: 2715 | K22: 2843
A23: Selling and admin | B23: 6508 | C23: 7105 | D23: 7645 | E23: 7523 | F23: 7783 | G23: 8046 | H23: 8674 | I23: 10562 | J23: 9815 | K23: 9964
A24: Other Expenses | B24: 1366 | C24: 1394 | D24: 1466 | E24: 1591 | F24: 2116 | G24: 2260 | H24: 2154 | I24: 2668 | J24: 2786 | K24: 2773
A25: Other Income | B25: 767 | C25: 507 | D25: 437 | E25: 536 | F25: 286 | G25: 359 | H25: 578 | I25: 884 | J25: 1632 | K25: 5572
A26: Depreciation | B26: 396 | C26: 478 | D26: 524 | E26: 938 | F26: 1012 | G26: 1025 | H26: 1030 | I26: 1097 | J26: 1122 | K26: 1186
A27: Interest | B27: 22 | C27: 20 | D27: 28 | E27: 106 | F27: 108 | G27: 98 | H27: 101 | I27: 302 | J27: 350 | K27: 363
... A31: Dividend Amount | B31: 3672 | C31: 4320 | D31: 4752 | E31: 5400 | F31: 9517.5 | G31: 7990 | H31: 9165 | I31: 9870 | J31: 12455 | K31: 9635
A32: EBITDA | B32: =SUM(B28,B27,B26) -> 6814 | C32: =SUM(C28,C27,C26) -> 7783 | D32: =SUM(D28,D27,D26) -> 9074 | E32: =SUM(E28,E27,E26) -> 10136 | F32: =SUM(F28,F27,F26) -> 11610 | G32: =SUM(G28,G27,G26) -> 12862 | H32: =SUM(H28,H27,H26) -> 14210 | I32: =SUM(I28,I27,I26) -> 15074 | ... K32: =SUM(K28,K27,K26) -> 20036
A33: EBIT | B33: =B28+B27 -> 6418 | C33: =C28+C27 -> 7305 | D33: =D28+D27 -> 8550 | E33: =E28+E27 -> 9198 | F33: =F28+F27 -> 10598 | G33: =G28+G27 -> 11837 | H33: =H28+H27 -> 13180 | I33: =I28+I27 -> 13977 | ... K33: =K28+K27 -> 18850
A40: Quarters
A41: Report Date | B41: 45382 | C41: 45473 | D41: 45565 | E41: 45657 | F41: 45747 | G41: 45838 | H41: 45930 | I41: 46022 | J41: 46112 | K41: 46203
A42: Sales | B42: 14857 | C42: 15339 | D42: 15508 | E42: 15146 | F42: 14734 | G42: 15174 | H42: 15263 | I42: 15805 | J42: 15733 | K42: 16657
A43: Expenses | B43: 11422 | C43: 11733 | D43: 11861 | E43: 11582 | F43: 11268 | G43: 11694 | H43: 11644 | I43: 12165 | J43: 12008 | K43: 12889
A44: Other Income | B44: 203 | C44: 209 | D44: 293 | E44: 814 | F44: 254 | G44: 149 | H44: 350 | I44: 4594 | J44: 479 | K44: 158
A45: Depreciation | B45: 289 | C45: 298 | D45: 305 | E45: 285 | F45: 284 | G45: 289 | H45: 288 | I45: 299 | J45: 310 | K45: 314
A46: Interest | B46: 102 | C46: 85 | D46: 99 | E46: 102 | F46: 72 | G46: 105 | H46: 106 | I46: 84 | J46: 68 | K46: 64
A47: Profit before tax | B47: 3247 | C47: 3432 | D47: 3536 | E47: 3991 | F47: 3364 | G47: 3235 | H47: 3575 | I47: 7851 | J47: 3826 | K47: 3548
A48: Tax | B48: 841 | C48: 894 | D48: 924 | E48: 990 | F48: 871 | G48: 503 | H48: 885 | I48: 776 | J48: 896 | K48: 917
A49: Net profit | B49: 2406 | C49: 2538 | D49: 2612 | E49: 3001 | F49: 2493 | G49: 2732 | H49: 2690 | I49: 7075 | J49: 2930 | K49: 2631
A50: Operating Profit | B50: 3435 | C50: 3606 | D50: 3647 | E50: 3564 | F50: 3466 | G50: 3480 | H50: 3619 | I50: 3640 | J50: 3725 | K50: 3768
A55: BALANCE SHEET
A56: Report Date | B56: 42825 | C56: 43190 | D56: 43555 | E56: 43921 | F56: 44286 | G56: 44651 | H56: 45016 | I56: 45382 | J56: 45747 | K56: 46112
A57: Equity Share Capital | B57: 216 | C57: 216 | D57: 216 | E57: 216 | F57: 235 | G57: 235 | H57: 235 | I57: 235 | J57: 235 | K57: 235
A58: Reserves | B58: 6274 | C58: 6859 | D58: 7443 | E58: 7815 | F58: 47199 | G58: 48525 | H58: 49986 | I58: 50738 | J58: 48918 | K58: 48988
A59: Borrowings | F59: 943 | G59: 971 | H59: 1039 | I59: 1374 | J59: 1537 | K59: 1325
...

Sheet Historical Financial Statement
B1: ="Historical Financial Statement for "&'Data Sheet'!B1 -> Historical Financial Statement for HINDUSTAN UNILEVER LTD
B2: ='Data Sheet'!A16 -> Report Date | C2: ='Data Sheet'!B16 -> 42825 | D2: ='Data Sheet'!C16 -> 43190 | E2: ='Data Sheet'!D16 -> 43555 | F2: ='Data Sheet'!E16 -> 43921 | G2: ='Data Sheet'!F16 -> 44286 | H2: ='Data Sheet'!G16 -> 44651 | I2: ='Data Sheet'!H16 -> 45016 | ... L2: ='Data Sheet'!K16 -> 46112 | M2: =L2+365 -> 46477 | N2: =M2+365 -> 46842 | O2: =N2+365 -> 47207 | P2: =O2+365 -> 47572 | Q2: =P2+365 -> 47937
M3: =L5*(1+0.07) -> 66313.25 | N3: =M5*(1+0.07) -> 74551.322 | O3: =N5*(1+0.07) -> 78581.333 | P3: =O5*(1+0.07) -> 82622.355 | Q3: =P5*(1+0.07) -> 86663.407 | R3: =_xlfn.RRI(15,C5,Q3) -> 0.068920524 | S3: =M3-L5 -> 4338.25 | T3: =N3-M3 -> 8238.0716 | U3: =O3-N3 -> 4030.0112 | V3: =P3-O3 -> 4041.0221 | W3: =Q3-P3 -> 4041.0523
A4: # | B4: Income Statement(in CR)
B5: ='Data Sheet'!A17 -> Sales | C5: ='Data Sheet'!B17 -> 31890 | D5: ='Data Sheet'!C17 -> 34525 | E5: ='Data Sheet'!D17 -> 38224 | F5: ='Data Sheet'!E17 -> 38785 | G5: ='Data Sheet'!F17 -> 45996 | H5: ='Data Sheet'!G17 -> 51193 | I5: ='Data Sheet'!H17 -> 59144 | ... L5: ='Data Sheet'!K17 -> 61975 | M5: =_xlfn.FORECAST.ETS(M$2,$C5:$L5,$C$2:$L$2) -> 69674.132 | N5: =_xlfn.FORECAST.ETS(N$2,$C5:$L5,$C$2:$L$2) -> 73440.498 | O5: =_xlfn.FORECAST.ETS(O$2,$C5:$L5,$C$2:$L$2) -> 77217.154 | P5: =_xlfn.FORECAST.ETS(P$2,$C5:$L5,$C$2:$L$2) -> 80993.839 | Q5: =_xlfn.FORECAST.ETS(Q$2,$C5:$L5,$C$2:$L$2) -> 84770.523 | R5: =(Q5/C5)^(1/15)-1 -> 0.067347956 | S5: =M5-L5 -> 7699.1323 | T5: =N5-M5 -> 3766.3656 | U5: =O5-N5 -> 3776.6562 | V5: =P5-O5 -> 3776.6844 | W5: =Q5-P5 -> 3776.6844
B6: Sales Growth In % | C6: =IFERROR((C5/B5)-1,(C5/C5)-1) -> 0 | D6: =IFERROR((D5/C5)-1,(D5/D5)-1) -> 0.082627783 | E6: =IFERROR((E5/D5)-1,(E5/E5)-1) -> 0.10713975 | F6: =IFERROR((F5/E5)-1,(F5/F5)-1) -> 0.014676643 | G6: =IFERROR((G5/F5)-1,(G5/G5)-1) -> 0.18592239 | H6: =IFERROR((H5/G5)-1,(H5/H5)-1) -> 0.11298809 | I6: =IFERROR((I5/H5)-1,(I5/I5)-1) -> 0.1553142 | J6: =IFERROR((J5/I5)-1,(J5/J5)-1) -> 0.022402949 | ... Q6: =IFERROR((Q5/P5)-1,(Q5/Q5)-1) -> 0.046629281
B7: COGS | C7: =SUM('Data Sheet'!B18,'Data Sheet'!B20:B22)-('Data Sheet'!B19) -> 17969 | D7: =SUM('Data Sheet'!C18,'Data Sheet'!C20:C22)-('Data Sheet'!C19) -> 18750 | E7: =SUM('Data Sheet'!D18,'Data Sheet'!D20:D22)-('Data Sheet'!D19) -> 20476 | F7: =SUM('Data Sheet'!E18,'Data Sheet'!E20:E22)-('Data Sheet'!E19) -> 20071 | G7: =SUM('Data Sheet'!F18,'Data Sheet'!F20:F22)-('Data Sheet'!F19) -> 24773 | H7: =SUM('Data Sheet'!G18,'Data Sheet'!G20:G22)-('Data Sheet'!G19) -> 28384 | I7: =SUM('Data Sheet'!H18,'Data Sheet'!H20:H22)-('Data Sheet'!H19) -> 34684 | J7: =SUM('Data Sheet'!I18,'Data Sheet'!I20:I22)-('Data Sheet'!I19) -> 33049 | ... L7: =SUM('Data Sheet'!K18,'Data Sheet'!K20:K22)-('Data Sheet'!K19) -> 34774 | M7: =Calculation!L5 -> 38311.555 | N7: =Calculation!M5 -> 40282.675 | O7: =Calculation!N5 -> 42396.074 | P7: =Calculation!O5 -> 44577.915 | Q7: =Calculation!P5 -> 46935.384
B8: Gross Profit | C8: =C5-C7 -> 13921 | D8: =D5-D7 -> 15775 | E8: =E5-E7 -> 17748 | F8: =F5-F7 -> 18714 | G8: =G5-G7 -> 21223 | H8: =H5-H7 -> 22809 | I8: =I5-I7 -> 24460 | J8: =J5-J7 -> 27420 | ... Q8: =Q5-Q7 -> 37835.139
B9: Gross Profit Margin | C9: =C8/C5 -> 0.43653183 | D9: =D8/D5 -> 0.45691528 | E9: =E8/E5 -> 0.46431561 | F9: =F8/F5 -> 0.48250612 | G9: =G8/G5 -> 0.46140969 | H9: =H8/H5 -> 0.4455492 | I9: =I8/I5 -> 0.41356689 | J9: =J8/J5 -> 0.45345549 | ... Q9: =Q8/Q5 -> 0.44632424
B11: ='Data Sheet'!A23 -> Selling and admin | C11: ='Data Sheet'!B23 -> 6508 | D11: ='Data Sheet'!C23 -> 7105 | E11: ='Data Sheet'!D23 -> 7645 | F11: ='Data Sheet'!E23 -> 7523 | G11: ='Data Sheet'!F23 -> 7783 | H11: ='Data Sheet'!G23 -> 8046 | I11: ='Data Sheet'!H23 -> 8674 | ... L11: ='Data Sheet'!K23 -> 9964 | M11: =Calculation!L9 -> 11298.279 | N11: =Calculation!M9 -> 11822.718 | O11: =Calculation!N9 -> 12479.779 | P11: =Calculation!O9 -> 13292.112 | Q11: =Calculation!P9 -> 13762.782
B12: ='Data Sheet'!A24 -> Other Expenses | C12: ='Data Sheet'!B24 -> 1366 | D12: ='Data Sheet'!C24 -> 1394 | E12: ='Data Sheet'!D24 -> 1466 | F12: ='Data Sheet'!E24 -> 1591 | G12: ='Data Sheet'!F24 -> 2116 | H12: ='Data Sheet'!G24 -> 2260 | I12: ='Data Sheet'!H24 -> 2154 | ... L12: ='Data Sheet'!K24 -> 2773 | M12: =Calculation!L13 -> 2959.1055 | N12: =Calculation!M13 -> 3116.3916 | O12: =Calculation!N13 -> 3292.54 | P12: =Calculation!O13 -> 3488.3011 | Q12: =Calculation!P13 -> 3668.3166
B13: EBITDA | C13: =C8-SUM(C11:C12) -> 6047 | D13: =D8-SUM(D11:D12) -> 7276 | E13: =E8-SUM(E11:E12) -> 8637 | F13: =F8-SUM(F11:F12) -> 9600 | G13: =G8-SUM(G11:G12) -> 11324 | H13: =H8-SUM(H11:H12) -> 12503 | I13: =I8-SUM(I11:I12) -> 13632 | J13: =J8-SUM(J11:J12) -> 14190 | ... Q13: =Q8-SUM(Q11:Q12) -> 20404.04
B14: EBITDA Margin | C14: =C13/C5 -> 0.18962057 | D14: =D13/D5 -> 0.21074584 | E14: =E13/E5 -> 0.22595751 | F14: =F13/F5 -> 0.24751837 | G14: =G13/G5 -> 0.24619532 | H14: =H13/H5 -> 0.24423261 | I14: =I13/I5 -> 0.2304883 | J14: =J13/J5 -> 0.2346657 | ... Q14: =Q13/Q5 -> 0.24069735
B16: ='Data Sheet'!A26 -> Depreciation | C16: ='Data Sheet'!B26 -> 396 | D16: ='Data Sheet'!C26 -> 478 | E16: ='Data Sheet'!D26 -> 524 | F16: ='Data Sheet'!E26 -> 938 | G16: ='Data Sheet'!F26 -> 1012 | H16: ='Data Sheet'!G26 -> 1025 | I16: ='Data Sheet'!H26 -> 1030 | ... L16: ='Data Sheet'!K26 -> 1186 | M16: =Calculation!L18 -> 1089.7051 | N16: =Calculation!M18 -> 1113.2103 | O16: =Calculation!N18 -> 1136.5066 | P16: =Calculation!O18 -> 1162.9514 | Q16: =Calculation!P18 -> 1184.64
B17: EBIT | C17: =C13-C16 -> 5651 | D17: =D13-D16 -> 6798 | E17: =E13-E16 -> 8113 | F17: =F13-F16 -> 8662 | G17: =G13-G16 -> 10312 | H17: =H13-H16 -> 11478 | I17: =I13-I16 -> 12602 | J17: =J13-J16 -> 13093 | ... Q17: =Q13-Q16 -> 19219.4
B18: EBIT Margin | C18: =C17/C5 -> 0.17720288 | D18: =D17/D5 -> 0.1969008 | E18: =E17/E5 -> 0.21224885 | F18: =F17/F5 -> 0.22333376 | G18: =G17/G5 -> 0.22419341 | H18: =H17/H5 -> 0.22421034 | I18: =I17/I5 -> 0.21307318 | J18: =J17/J5 -> 0.21652417 | ... Q18: =Q17/Q5 -> 0.22672268
B20: ='Data Sheet'!A27 -> Interest | C20: ='Data Sheet'!B27 -> 22 | D20: ='Data Sheet'!C27 -> 20 | E20: ='Data Sheet'!D27 -> 28 | F20: ='Data Sheet'!E27 -> 106 | G20: ='Data Sheet'!F27 -> 108 | H20: ='Data Sheet'!G27 -> 98 | I20: ='Data Sheet'!H27 -> 101 | ... L20: ='Data Sheet'!K27 -> 363 | M20: =Calculation!R31 -> 228.37228 | N20: =Calculation!S31 -> 241.14271 | O20: =Calculation!T31 -> 259.04514 | P20: =Calculation!U31 -> 280.75238 | Q20: =Calculation!V31 -> 279.00611
B21: ='Data Sheet'!A25 -> Other Income | C21: ='Data Sheet'!B25 -> 767 | D21: ='Data Sheet'!C25 -> 507 | E21: ='Data Sheet'!D25 -> 437 | F21: ='Data Sheet'!E25 -> 536 | G21: ='Data Sheet'!F25 -> 286 | H21: ='Data Sheet'!G25 -> 359 | I21: ='Data Sheet'!H25 -> 578 | ... L21: ='Data Sheet'!K25 -> 5572 | M21: =Calculation!L31 -> 1798.4906 | N21: =Calculation!M31 -> 2135.5552 | O21: =Calculation!N31 -> 2529.3549 | P21: =Calculation!O31 -> 2963.3209 | Q21: =Calculation!P31 -> 3411.8705
B22: EBT | C22: =(C17+C21)-C20 -> 6396 | D22: =(D17+D21)-D20 -> 7285 | E22: =(E17+E21)-E20 -> 8522 | F22: =(F17+F21)-F20 -> 9092 | G22: =(G17+G21)-G20 -> 10490 | H22: =(H17+H21)-H20 -> 11739 | I22: =(I17+I21)-I20 -> 13079 | J22: =(J17+J21)-J20 -> 13675 | ... Q22: =(Q17+Q21)-Q20 -> 22352.264
B23: EBT Margin | C23: =C22/C5 -> 0.20056444 | D23: =D22/D5 -> 0.21100652 | E23: =E22/E5 -> 0.22294893 | F23: =F22/F5 -> 0.23442052 | G23: =G22/G5 -> 0.22806331 | H23: =H22/H5 -> 0.22930869 | I23: =I22/I5 -> 0.22113824 | J23: =J22/J5 -> 0.22614894 | ... Q23: =Q22/Q5 -> 0.26367968
B25: ='Data Sheet'!A29 -> Tax | C25: ='Data Sheet'!B29 -> 1906 | D25: ='Data Sheet'!C29 -> 2048 | E25: ='Data Sheet'!D29 -> 2486 | F25: ='Data Sheet'!E29 -> 2354 | G25: ='Data Sheet'!F29 -> 2536 | H25: ='Data Sheet'!G29 -> 2921 | I25: ='Data Sheet'!H29 -> 3117 | ... L25: ='Data Sheet'!K29 -> 3060 | M25: =Calculation!L37 -> 4401.0339 | N25: =Calculation!M37 -> 4593.6818 | O25: =Calculation!N37 -> 4751.7347 | P25: =Calculation!O37 -> 4824.3691 | Q25: =Calculation!P37 -> 4999.0492
B26: Net Profit | C26: =C22-C25 -> 4490 | D26: =D22-D25 -> 5237 | E26: =E22-E25 -> 6036 | F26: =F22-F25 -> 6738 | G26: =G22-G25 -> 7954 | H26: =H22-H25 -> 8818 | I26: =I22-I25 -> 9962 | J26: =J22-J25 -> 10114 | ... Q26: =Q22-Q25 -> 17353.215
B27: Net Profit Margin | C27: =C26/C5 -> 0.14079649 | D27: =D26/D5 -> 0.15168718 | E27: =E26/E5 -> 0.15791126 | F27: =F26/F5 -> 0.17372696 | G27: =G26/G5 -> 0.17292808 | H27: =H26/H5 -> 0.17225011 | I27: =I26/I5 -> 0.16843636 | J27: =J26/J5 -> 0.16725926 | ... Q27: =Q26/Q5 -> 0.20470813
A30: # | B30: Balance Sheet(in CR)
B31: ='Data Sheet'!A57 -> Equity Share Capital | C31: ='Data Sheet'!B57 -> 216 | D31: ='Data Sheet'!C57 -> 216 | E31: ='Data Sheet'!D57 -> 216 | F31: ='Data Sheet'!E57 -> 216 | G31: ='Data Sheet'!F57 -> 235 | H31: ='Data Sheet'!G57 -> 235 | I31: ='Data Sheet'!H57 -> 235 | ... K31: ='Data Sheet'!J57 -> 235 | L31: ='Data Sheet'!$K57 -> 235 | M31: ='Data Sheet'!$K57 -> 235 | N31: ='Data Sheet'!$K57 -> 235 | O31: ='Data Sheet'!$K57 -> 235 | P31: ='Data Sheet'!$K57 -> 235 | Q31: ='Data Sheet'!$K57 -> 235
B32: ='Data Sheet'!A58 -> Reserves | C32: ='Data Sheet'!B58 -> 6274 | D32: ='Data Sheet'!C58 -> 6859 | E32: ='Data Sheet'!D58 -> 7443 | F32: ='Data Sheet'!E58 -> 7815 | G32: ='Data Sheet'!F58 -> 47199 | H32: ='Data Sheet'!G58 -> 48525 | I32: ='Data Sheet'!H58 -> 49986 | ... L32: ='Data Sheet'!K58 -> 48988 | M32: =Calculation!R44 -> 50800.956 | N32: =Calculation!S44 -> 52681.921 | O32: =Calculation!T44 -> 54503.012 | P32: =Calculation!U44 -> 56219.91 | Q32: =Calculation!V44 -> 57829.611
B34: Liabilities
B35: Current Liabilities
B36: ='Manual Data'!B39 -> Trade Payables | C36: ='Manual Data'!C39 -> 6006 | D36: ='Manual Data'!D39 -> 7013 | E36: ='Manual Data'!E39 -> 7070 | F36: ='Manual Data'!F39 -> 7399 | G36: ='Manual Data'!G39 -> 8627 | H36: ='Manual Data'!H39 -> 8864 | I36: ='Manual Data'!I39 -> 9391 | ... L36: ='Manual Data'!L39 -> 12913 | M36: =Calculation!L46 -> 12895.106 | N36: =Calculation!M46 -> 13567.994 | O36: =Calculation!N46 -> 14122.085 | P36: =Calculation!O46 -> 14794.543 | Q36: =Calculation!P46 -> 15404.403
B37: ='Manual Data'!B40 -> Advance from Customers | C37: ='Manual Data'!C40 -> 70 | D37: ='Manual Data'!D40 -> 55 | E37: ='Manual Data'!E40 -> 39 | F37: ='Manual Data'!F40 -> 154 | G37: ='Manual Data'!G40 -> 93 | H37: ='Manual Data'!H40 -> 113 | I37: ='Manual Data'!I40 -> 86 | ... L37: ='Manual Data'!L40 -> 0 | M37: =Calculation!L50 -> 111.01986 | N37: =Calculation!M50 -> 112.60285 | O37: =Calculation!N50 -> 117.93169 | P37: =Calculation!O50 -> 127.80588 | Q37: =Calculation!P50 -> 113.48286
B38: Total Current Liabilities | C38: =SUM(C36:C37) -> 6076 | D38: =SUM(D36:D37) -> 7068 | E38: =SUM(E36:E37) -> 7109 | F38: =SUM(F36:F37) -> 7553 | G38: =SUM(G36:G37) -> 8720 | H38: =SUM(H36:H37) -> 8977 | I38: =SUM(I36:I37) -> 9477 | J38: =SUM(J36:J37) -> 10237 | ... Q38: =SUM(Q36:Q37) -> 15517.886
B40: Non-Current Liabilities
B41: ='Data Sheet'!A59 -> Borrowings | C41: ='Data Sheet'!B59 -> 0 | D41: ='Data Sheet'!C59 -> 0 | E41: ='Data Sheet'!D59 -> 0 | F41: ='Data Sheet'!E59 -> 0 | G41: ='Data Sheet'!F59 -> 943 | H41: ='Data Sheet'!G59 -> 971 | I41: ='Data Sheet'!H59 -> 1039 | ... K41: ='Data Sheet'!J59 -> 1537 | L41: ='Data Sheet'!$K$59 -> 1325 | M41: =Calculation!R30 -> 1325 | N41: =Calculation!S30 -> 1325 | O41: =Calculation!T30 -> 1325 | P41: =Calculation!U30 -> 1325 | Q41: =Calculation!V30 -> 1325
B42: ='Data Sheet'!A60 -> Other Liabilities | C42: ='Data Sheet'!B60-SUM(C36:C37) -> 2185 | D42: ='Data Sheet'!C60-SUM(D36:D37) -> 3006 | E42: ='Data Sheet'!D60-SUM(E36:E37) -> 3097 | F42: ='Data Sheet'!E60-SUM(F36:F37) -> 4018 | G42: ='Data Sheet'!F60-SUM(G36:G37) -> 11019 | H42: ='Data Sheet'!G60-SUM(H36:H37) -> 11029 | I42: ='Data Sheet'!H60-SUM(I36:I37) -> 11088 | J42: ='Data Sheet'!I60-SUM(J36:J37) -> 14492 | ... L42: ='Data Sheet'!K60-SUM(L36:L37) -> 14521 | M42: =Calculation!L54 -> 12090.09 | N42: =Calculation!M54 -> 13514.816 | O42: =Calculation!N54 -> 14958.484 | P42: =Calculation!O54 -> 16602.88 | Q42: =Calculation!P54 -> 18236.572
B43: Total Non-Current Liabilities | C43: =SUM(C41:C42) -> 2185 | D43: =SUM(D41:D42) -> 3006 | E43: =SUM(E41:E42) -> 3097 | F43: =SUM(F41:F42) -> 4018 | G43: =SUM(G41:G42) -> 11962 | H43: =SUM(H41:H42) -> 12000 | I43: =SUM(I41:I42) -> 12127 | J43: =SUM(J41:J42) -> 15866 | ... Q43: =SUM(Q41:Q42) -> 19561.572
B45: Total Liabilities | C45: =SUM(C43,C38,C31:C32) -> 14751 | D45: =SUM(D43,D38,D31:D32) -> 17149 | E45: =SUM(E43,E38,E31:E32) -> 17865 | F45: =SUM(F43,F38,F31:F32) -> 19602 | G45: =SUM(G43,G38,G31:G32) -> 68116 | H45: =SUM(H43,H38,H31:H32) -> 69737 | I45: =SUM(I43,I38,I31:I32) -> 71825 | J45: =SUM(J43,J38,J31:J32) -> 77076 | ... Q45: =SUM(Q43,Q38,Q31:Q32) -> 93144.068
B47: Assets
B48: Non-Current Assets
B49: ='Data Sheet'!A62 -> Net Block | C49: ='Data Sheet'!B62 -> 4024 | D49: ='Data Sheet'!C62 -> 4142 | E49: ='Data Sheet'!D62 -> 4343 | F49: ='Data Sheet'!E62 -> 5056 | G49: ='Data Sheet'!F62 -> 51027 | H49: ='Data Sheet'!G62 -> 51034 | I49: ='Data Sheet'!H62 -> 51405 | ... L49: ='Data Sheet'!K62 -> 52419 | M49: =Calculation!R24 -> 53285.88 | N49: =Calculation!S24 -> 54205.437 | O49: =Calculation!T24 -> 55229.184 | P49: =Calculation!U24 -> 56404.477 | Q49: =Calculation!V24 -> 57744.637
B50: ='Data Sheet'!A63 -> Capital Work in Progress | C50: ='Data Sheet'!B63 -> 203 | D50: ='Data Sheet'!C63 -> 430 | E50: ='Data Sheet'!D63 -> 373 | F50: ='Data Sheet'!E63 -> 513 | G50: ='Data Sheet'!F63 -> 623 | H50: ='Data Sheet'!G63 -> 901 | I50: ='Data Sheet'!H63 -> 1020 | ... L50: ='Data Sheet'!K63 -> 833 | M50: =Calculation!L58 -> 2359.2155 | N50: =Calculation!M58 -> 2366.4696 | O50: =Calculation!N58 -> 2078.9207 | P50: =Calculation!O58 -> 1851.045 | Q50: =Calculation!P58 -> 1498.6302
...

Sheet Calculation
A3: ='Historical Financial Statement'!B2 -> Report Date | B3: ='Historical Financial Statement'!C2 -> 42825 | C3: ='Historical Financial Statement'!D2 -> 43190 | D3: ='Historical Financial Statement'!E2 -> 43555 | E3: ='Historical Financial Statement'!F2 -> 43921 | F3: ='Historical Financial Statement'!G2 -> 44286 | G3: ='Historical Financial Statement'!H2 -> 44651 | H3: ='Historical Financial Statement'!I2 -> 45016 | ... P3: ='Historical Financial Statement'!Q2 -> 47937
A4: ='Historical Financial Statement'!B5 -> Sales | B4: ='Historical Financial Statement'!C5 -> 31890 | C4: ='Historical Financial Statement'!D5 -> 34525 | D4: ='Historical Financial Statement'!E5 -> 38224 | E4: ='Historical Financial Statement'!F5 -> 38785 | F4: ='Historical Financial Statement'!G5 -> 45996 | G4: ='Historical Financial Statement'!H5 -> 51193 | H4: ='Historical Financial Statement'!I5 -> 59144 | ... P4: ='Historical Financial Statement'!Q5 -> 84770.523
A5: ='Historical Financial Statement'!B7 -> COGS | B5: ='Historical Financial Statement'!C7 -> 17969 | C5: ='Historical Financial Statement'!D7 -> 18750 | D5: ='Historical Financial Statement'!E7 -> 20476 | E5: ='Historical Financial Statement'!F7 -> 20071 | F5: ='Historical Financial Statement'!G7 -> 24773 | G5: ='Historical Financial Statement'!H7 -> 28384 | H5: ='Historical Financial Statement'!I7 -> 34684 | ... K5: ='Historical Financial Statement'!L7 -> 34774 | L5: =L4*$B$7 -> 38311.555 | M5: =M4*C7 -> 40282.675 | N5: =N4*D7 -> 42396.074 | O5: =O4*E7 -> 44577.915 | P5: =P4*F7 -> 46935.384
A6: COGS(%) | B6: =B5/B4 -> 0.56346817 | C6: =C5/C4 -> 0.54308472 | D6: =D5/D4 -> 0.53568439 | E6: =E5/E4 -> 0.51749388 | F6: =F5/F4 -> 0.53859031 | G6: =G5/G4 -> 0.5544508 | H6: =H5/H4 -> 0.58643311 | I6: =I5/I4 -> 0.54654451 | ... P6: =P5/P4 -> 0.55367576
A7: AvgCOGS(%) | B7: =AVERAGE(B6:K6) -> 0.5498677 | C7: =AVERAGE(C6:L6) -> 0.54850765 | D7: =AVERAGE(D6:M6) -> 0.54904995 | E7: =AVERAGE(E6:N6) -> 0.5503865 | F7: =AVERAGE(F6:O6) -> 0.55367576
A9: ='Historical Financial Statement'!B11 -> Selling and admin | B9: ='Historical Financial Statement'!C11 -> 6508 | C9: ='Historical Financial Statement'!D11 -> 7105 | D9: ='Historical Financial Statement'!E11 -> 7645 | E9: ='Historical Financial Statement'!F11 -> 7523 | F9: ='Historical Financial Statement'!G11 -> 7783 | G9: ='Historical Financial Statement'!H11 -> 8046 | H9: ='Historical Financial Statement'!I11 -> 8674 | ... K9: ='Historical Financial Statement'!L11 -> 9964 | L9: =L4*$B$11 -> 11298.279 | M9: =M4*C11 -> 11822.718 | N9: =N4*D11 -> 12479.779 | O9: =O4*E11 -> 13292.112 | P9: =P4*F11 -> 13762.782
A10: (%) | B10: =B9/B4 -> 0.20407651 | C10: =C9/C4 -> 0.2057929 | D10: =D9/D4 -> 0.20000523 | E10: =E9/E4 -> 0.19396674 | F10: =F9/F4 -> 0.16921037 | G10: =G9/G4 -> 0.15716993 | H10: =H9/H4 -> 0.146659 | I10: =I9/I4 -> 0.17466801 | ... P10: =P9/P4 -> 0.1623534
A11: Avg | B11: =AVERAGE(F10:K10) -> 0.16215888 | C11: =AVERAGE(G10:L10) -> 0.16098363 | D11: =AVERAGE(H10:M10) -> 0.16161925 | E11: =AVERAGE(I10:N10) -> 0.16411263 | F11: =AVERAGE(J10:O10) -> 0.1623534
A13: ='Historical Financial Statement'!B12 -> Other Expenses | B13: ='Historical Financial Statement'!C12 -> 1366 | C13: ='Historical Financial Statement'!D12 -> 1394 | D13: ='Historical Financial Statement'!E12 -> 1466 | E13: ='Historical Financial Statement'!F12 -> 1591 | F13: ='Historical Financial Statement'!G12 -> 2116 | G13: ='Historical Financial Statement'!H12 -> 2260 | H13: ='Historical Financial Statement'!I12 -> 2154 | ... K13: ='Historical Financial Statement'!L12 -> 2773 | L13: =L4*B15 -> 2959.1055 | M13: =C15*M4 -> 3116.3916 | N13: =D15*N4 -> 3292.54 | O13: =E15*O4 -> 3488.3011 | P13: =P4*F15 -> 3668.3166
B14: =B13/B4 -> 0.042834744 | C14: =C13/C4 -> 0.040376539 | D14: =D13/D4 -> 0.038352867 | E14: =E13/E4 -> 0.041021013 | F14: =F13/F4 -> 0.046004 | G14: =G13/G4 -> 0.044146661 | H14: =H13/H4 -> 0.036419586 | I14: =I13/I4 -> 0.044121781 | ... P14: =P13/P4 -> 0.043273493
B15: =AVERAGE(B14:K14) -> 0.042470648 | C15: =AVERAGE(C14:L14) -> 0.042434238 | D15: =AVERAGE(D14:M14) -> 0.042640008 | E15: =AVERAGE(E14:N14) -> 0.043068722 | F15: =AVERAGE(F14:O14) -> 0.043273493
A17: ='Historical Financial Statement'!B49 -> Net Block | B17: ='Historical Financial Statement'!C49 -> 4024 | C17: ='Historical Financial Statement'!D49 -> 4142 | D17: ='Historical Financial Statement'!E49 -> 4343 | E17: ='Historical Financial Statement'!F49 -> 5056 | F17: ='Historical Financial Statement'!G49 -> 51027 | G17: ='Historical Financial Statement'!H49 -> 51034 | H17: ='Historical Financial Statement'!I49 -> 51405 | ... K17: ='Historical Financial Statement'!L49 -> 52419 | L17: =R24 -> 53285.88 | M17: =S24 -> 54205.437 | N17: =T24 -> 55229.184 | O17: =U24 -> 56404.477 | P17: =V24 -> 57744.637
A18: ='Historical Financial Statement'!B16 -> Depreciation | B18: ='Historical Financial Statement'!C16 -> 396 | C18: ='Historical Financial Statement'!D16 -> 478 | D18: ='Historical Financial Statement'!E16 -> 524 | E18: ='Historical Financial Statement'!F16 -> 938 | F18: ='Historical Financial Statement'!G16 -> 1012 | G18: ='Historical Financial Statement'!H16 -> 1025 | H18: ='Historical Financial Statement'!I16 -> 1030 | ... K18: ='Historical Financial Statement'!L16 -> 1186 | L18: =K17*B20 -> 1089.7051 | M18: =L17*C20 -> 1113.2103 | N18: =D20*M17 -> 1136.5066 | O18: =E20*N17 -> 1162.9514 | P18: =F20*O17 -> 1184.64
B19: =B18/B17 -> 0.098409543 | C19: =C18/C17 -> 0.11540319 | D19: =D18/D17 -> 0.12065393 | E19: =E18/E17 -> 0.18552215 | F19: =F18/F17 -> 0.019832638 | G19: =G18/G17 -> 0.020084649 | H19: =H18/H17 -> 0.020036961 | I19: =I18/I17 -> 0.020943508 | ... P19: =P18/P17 -> 0.020515152 | R19: Fixed Assets Schedule
B20: =AVERAGE(F19:K19) -> 0.020788361 | C20: =AVERAGE(G19:L19) -> 0.020891282 | D20: =AVERAGE(H19:M19) -> 0.020966653 | E20: =AVERAGE(I19:N19) -> 0.021056828 | F20: =AVERAGE(J19:O19) -> 0.021002588 | R20: =L3 -> 46477 | S20: =M3 -> 46842 | T20: =N3 -> 47207 | U20: =O3 -> 47572 | V20: =P3 -> 47937
R21: =L4*B24 -> 1956.5852 | S21: =M4*C24 -> 2032.7671 | T21: =N4*D24 -> 2160.2533 | U21: =O4*E24 -> 2338.2444 | V21: =P4*F24 -> 2524.8001
A22: fixied assets purchased | B22: =-'Manual Data'!C15 -> 1024 | C22: =-'Manual Data'!D15 -> 853 | D22: =-'Manual Data'!E15 -> 728 | E22: =-'Manual Data'!F15 -> 765 | F22: =-'Manual Data'!G15 -> 4051 | G22: =-'Manual Data'!H15 -> 919 | H22: =-'Manual Data'!I15 -> 1041 | I22: =-'Manual Data'!J15 -> 1318 | ... K22: =-'Manual Data'!L15 -> 1274 | L22: =R21 -> 1956.5852 | M22: =S21 -> 2032.7671 | N22: =T21 -> 2160.2533 | O22: =U21 -> 2338.2444 | P22: =V21 -> 2524.8001 | R22: =K17 -> 52419 | S22: =L17 -> 53285.88 | T22: =M17 -> 54205.437 | U22: =N17 -> 55229.184 | V22: =O17 -> 56404.477 | W22: Opening
B23: =B22/B4 -> 0.032110379 | C23: =C22/C4 -> 0.024706734 | D23: =D22/D4 -> 0.019045626 | E23: =E22/E4 -> 0.01972412 | F23: =F22/F4 -> 0.088072876 | G23: =G22/G4 -> 0.017951673 | H23: =H22/H4 -> 0.017601109 | I23: =I22/I4 -> 0.021796292 | ... P23: =P22/P4 -> 0.02978394 | R23: =-L18 -> -1089.7051 | S23: =-M18 -> -1113.2103 | T23: =-N18 -> -1136.5066 | U23: =-O18 -> -1162.9514 | V23: =-P18 -> -1184.64
B24: =AVERAGE(B23:K23) -> 0.028081946 | C24: =AVERAGE(C23:L23) -> 0.027679102 | D24: =AVERAGE(D23:M23) -> 0.027976339 | E24: =AVERAGE(E23:N23) -> 0.028869411 | F24: =AVERAGE(F23:O23) -> 0.02978394 | R24: =SUM(R21:R23) -> 53285.88 | S24: =SUM(S21:S23) -> 54205.437 | T24: =SUM(T21:T23) -> 55229.184 | U24: =SUM(U21:U23) -> 56404.477 | V24: =SUM(V21:V23) -> 57744.637 | W24: Closing
R25: Debt Schedule
R26: =R20 -> 46477 | S26: =S20 -> 46842 | T26: =T20 -> 47207 | U26: =U20 -> 47572 | V26: =V20 -> 47937
A27: intrest | F27: ='Historical Financial Statement'!G20 -> 108 | G27: ='Historical Financial Statement'!H20 -> 98 | H27: ='Historical Financial Statement'!I20 -> 101 | I27: ='Historical Financial Statement'!J20 -> 302 | J27: ='Historical Financial Statement'!K20 -> 350 | K27: ='Historical Financial Statement'!L20 -> 363 | L27: =R31 -> 228.37228 | M27: =S31 -> 241.14271 | N27: =T31 -> 259.04514 | O27: =U31 -> 280.75238 | P27: =V31 -> 279.00611 | R27: ='Historical Financial Statement'!L41 -> 1325 | S27: =R30 -> 1325 | T27: =S30 -> 1325 | U27: =T30 -> 1325 | V27: =U30 -> 1325
A28: % | F28: =F27/'Historical Financial Statement'!G41 -> 0.1145281 | G28: =G27/'Historical Financial Statement'!H41 -> 0.10092688 | H28: =H27/'Historical Financial Statement'!I41 -> 0.097208855 | I28: =I27/'Historical Financial Statement'!J41 -> 0.21979622 | J28: =J27/'Historical Financial Statement'!K41 -> 0.22771633 | K28: =K27/'Historical Financial Statement'!L41 -> 0.27396226 | L28: =L27/R30 -> 0.17235644 | M28: =M27/S30 -> 0.1819945 | N28: =N27/T30 -> 0.19550577 | O28: =O27/U30 -> 0.21188859 | P28: =P27/V30 -> 0.21057065 | R28: ='Historical Financial Statement'!$L$95 -> -464 | S28: ='Historical Financial Statement'!$L$95 -> -464 | T28: ='Historical Financial Statement'!$L$95 -> -464 | U28: ='Historical Financial Statement'!$L$95 -> -464 | V28: ='Historical Financial Statement'!$L$95 -> -464
F29: =AVERAGE(F28:K28) -> 0.17235644 | G29: =AVERAGE(G28:L28) -> 0.1819945 | H29: =AVERAGE(H28:M28) -> 0.19550577 | I29: =AVERAGE(I28:N28) -> 0.21188859 | J29: =AVERAGE(J28:O28) -> 0.21057065 | R29: =-R28 -> 464 | S29: =-S28 -> 464 | T29: =-T28 -> 464 | U29: =-U28 -> 464 | V29: =-V28 -> 464
R30: =SUM(R27:R29) -> 1325 | S30: =SUM(S27:S29) -> 1325 | T30: =SUM(T27:T29) -> 1325 | U30: =SUM(U27:U29) -> 1325 | V30: =SUM(V27:V29) -> 1325
A31: ='Historical Financial Statement'!B21 -> Other Income | B31: ='Historical Financial Statement'!C21 -> 767 | C31: ='Historical Financial Statement'!D21 -> 507 | D31: ='Historical Financial Statement'!E21 -> 437 | E31: ='Historical Financial Statement'!F21 -> 536 | F31: ='Historical Financial Statement'!G21 -> 286 | G31: ='Historical Financial Statement'!H21 -> 359 | H31: ='Historical Financial Statement'!I21 -> 578 | ... K31: ='Historical Financial Statement'!L21 -> 5572 | L31: =L4*B33 -> 1798.4906 | M31: =M4*C33 -> 2135.5552 | N31: =N4*D33 -> 2529.3549 | O31: =O4*E33 -> 2963.3209 | P31: =P4*F33 -> 3411.8705 | R31: =AVERAGE(R27,R30)*F29 -> 228.37228 | S31: =AVERAGE(S27,S30)*G29 -> 241.14271 | T31: =AVERAGE(T27,T30)*H29 -> 259.04514 | U31: =AVERAGE(U27,U30)*I29 -> 280.75238 | V31: =AVERAGE(V27,V30)*J29 -> 279.00611
B32: =B31/B4 -> 0.024051427 | C32: =C31/C4 -> 0.014685011 | D32: =D31/D4 -> 0.011432608 | E32: =E31/E4 -> 0.013819776 | F32: =F31/F4 -> 0.006217932 | G32: =G31/G4 -> 0.0070126775 | H32: =H31/H4 -> 0.009772758 | I32: =I31/I4 -> 0.014619061 | ... P32: =P31/P4 -> 0.040248313
B33: =AVERAGE(F32:K32) -> 0.025812888 | C33: =AVERAGE(G32:L32) -> 0.029078714 | D33: =AVERAGE(H32:M32) -> 0.032756386 | E33: =AVERAGE(I32:N32) -> 0.036586991 | F33: =AVERAGE(J32:O32) -> 0.040248313
A36: ='Historical Financial Statement'!B17 -> EBIT | B36: ='Historical Financial Statement'!C17 -> 5651 | C36: ='Historical Financial Statement'!D17 -> 6798 | D36: ='Historical Financial Statement'!E17 -> 8113 | E36: ='Historical Financial Statement'!F17 -> 8662 | F36: ='Historical Financial Statement'!G17 -> 10312 | G36: ='Historical Financial Statement'!H17 -> 11478 | H36: ='Historical Financial Statement'!I17 -> 12602 | ... P36: ='Historical Financial Statement'!Q17 -> 19219.4
A37: ='Historical Financial Statement'!B25 -> Tax | B37: ='Historical Financial Statement'!C25 -> 1906 | C37: ='Historical Financial Statement'!D25 -> 2048 | D37: ='Historical Financial Statement'!E25 -> 2486 | E37: ='Historical Financial Statement'!F25 -> 2354 | F37: ='Historical Financial Statement'!G25 -> 2536 | G37: ='Historical Financial Statement'!H25 -> 2921 | H37: ='Historical Financial Statement'!I25 -> 3117 | ... K37: ='Historical Financial Statement'!L25 -> 3060 | L37: =B39*L36 -> 4401.0339 | M37: =C39*M36 -> 4593.6818 | N37: =N36*D39 -> 4751.7347 | O37: =E39*O36 -> 4824.3691 | P37: =F39*P36 -> 4999.0492
B38: =B37/B36 -> 0.33728544 | C38: =C37/C36 -> 0.30126508 | D38: =D37/D36 -> 0.30642179 | E38: =E37/E36 -> 0.27176172 | F38: =F37/F36 -> 0.24592708 | G38: =G37/G36 -> 0.25448684 | H38: =H37/H36 -> 0.24734169 | I38: =I37/I36 -> 0.27197739 | ... P38: =P37/P36 -> 0.26010433
B39: =AVERAGE(B38:K38) -> 0.27479862 | C39: =AVERAGE(C38:L38) -> 0.26854994 | D39: =AVERAGE(D38:M38) -> 0.26527843 | E39: =AVERAGE(E38:N38) -> 0.26116409 | F39: =AVERAGE(F38:O38) -> 0.26010433 | R39: Reserve Schedule
R40: =R26 -> 46477 | S40: =S26 -> 46842 | T40: =T26 -> 47207 | U40: =U26 -> 47572 | V40: =V26 -> 47937
A41: ='Historical Financial Statement'!B31 -> Equity Share Capital | B41: ='Historical Financial Statement'!C31 -> 216 | C41: ='Historical Financial Statement'!D31 -> 216 | D41: ='Historical Financial Statement'!E31 -> 216 | E41: ='Historical Financial Statement'!F31 -> 216 | F41: ='Historical Financial Statement'!G31 -> 235 | G41: ='Historical Financial Statement'!H31 -> 235 | H41: ='Historical Financial Statement'!I31 -> 235 | ... K41: ='Historical Financial Statement'!L31 -> 235 | R41: ='Historical Financial Statement'!L32 -> 48988 | S41: =R44 -> 50800.956 | T41: =S44 -> 52681.921 | U41: =T44 -> 54503.012 | V41: =U44 -> 56219.91
A42: ='Historical Financial Statement'!B94 -> Dividends paid | B42: ='Historical Financial Statement'!C94 -> -3561 | C42: ='Historical Financial Statement'!D94 -> -3896 | D42: ='Historical Financial Statement'!E94 -> -4546 | E42: ='Historical Financial Statement'!F94 -> -5196 | F42: ='Historical Financial Statement'!G94 -> -8811 | G42: ='Historical Financial Statement'!H94 -> -7519 | H42: ='Historical Financial Statement'!I94 -> -8459 | ... K42: ='Historical Financial Statement'!L94 -> -10103 | L42: =R43 -> -11371.616 | M42: =S43 -> -12525.269 | N42: =T43 -> -13609.739 | O42: =U43 -> -14613.86 | P42: =V43 -> -15743.515 | R42: ='Historical Financial Statement'!M26 -> 13184.572 | S42: ='Historical Financial Statement'!N26 -> 14406.233 | T42: ='Historical Financial Statement'!O26 -> 15430.83 | U42: ='Historical Financial Statement'!P26 -> 16330.758 | V42: ='Historical Financial Statement'!Q26 -> 17353.215
A43: Dividend paid (%) | B43: =ABS(B42/'Historical Financial Statement'!C26) -> 0.79309577 | C43: =ABS(C42/'Historical Financial Statement'!D26) -> 0.74393737 | D43: =ABS(D42/'Historical Financial Statement'!E26) -> 0.75314778 | E43: =ABS(E42/'Historical Financial Statement'!F26) -> 0.77114871 | F43: =ABS(F42/'Historical Financial Statement'!G26) -> 1.1077445 | G43: =ABS(G42/'Historical Financial Statement'!H26) -> 0.85268768 | H43: =ABS(H42/'Historical Financial Statement'!I26) -> 0.84912668 | I43: =ABS(I42/'Historical Financial Statement'!J26) -> 0.92920704 | ... P43: =ABS(P42/'Historical Financial Statement'!Q26) -> 0.90723905 | R43: =-'Historical Financial Statement'!M26*Calculation!B44 -> -11371.616 | S43: =-'Historical Financial Statement'!N26*Calculation!C44 -> -12525.269 | T43: =-'Historical Financial Statement'!O26*Calculation!D44 -> -13609.739 | U43: =-'Historical Financial Statement'!P26*Calculation!E44 -> -14613.86 | V43: =-'Historical Financial Statement'!Q26*Calculation!F44 -> -15743.515
A44: Average | B44: =AVERAGE(B43:K43) -> 0.86249412 | C44: =AVERAGE(C43:L43) -> 0.86943396 | D44: =AVERAGE(D43:M43) -> 0.88198362 | E44: =AVERAGE(E43:N43) -> 0.8948672 | F44: =AVERAGE(F43:O43) -> 0.90723905 | R44: =SUM(R41:R43) -> 50800.956 | S44: =SUM(S41:S43) -> 52681.921 | T44: =SUM(T41:T43) -> 54503.012 | U44: =SUM(U41:U43) -> 56219.91 | V44: =SUM(V41:V43) -> 57829.611
A46: ='Historical Financial Statement'!B36 -> Trade Payables | B46: ='Historical Financial Statement'!C36 -> 6006 | C46: ='Historical Financial Statement'!D36 -> 7013 | D46: ='Historical Financial Statement'!E36 -> 7070 | E46: ='Historical Financial Statement'!F36 -> 7399 | F46: ='Historical Financial Statement'!G36 -> 8627 | G46: ='Historical Financial Statement'!H36 -> 8864 | H46: ='Historical Financial Statement'!I36 -> 9391 | ... K46: ='Historical Financial Statement'!L36 -> 12913 | L46: =(L5*B48)/365 -> 12895.106 | M46: =(M5*C48)/365 -> 13567.994 | N46: =(N5*D48)/365 -> 14122.085 | O46: =(O5*E48)/365 -> 14794.543 | P46: =(P5*F48)/365 -> 15404.403
A47: ='Ratio Analysis'!B36 -> Payable Days | B47: ='Ratio Analysis'!C36 -> 121.99844 | C47: ='Ratio Analysis'!D36 -> 136.51973 | D47: ='Ratio Analysis'!E36 -> 126.02803 | E47: ='Ratio Analysis'!F36 -> 134.55408 | F47: ='Ratio Analysis'!G36 -> 127.10834 | G47: ='Ratio Analysis'!H36 -> 113.98534 | H47: ='Ratio Analysis'!I36 -> 98.826981 | ... K47: ='Ratio Analysis'!L36 -> 135.53934 | L47: =365/(L5/L46) -> 122.85363 | M47: =365/(M5/M46) -> 122.93915 | N47: =365/(N5/N46) -> 121.5811 | O47: =365/(O5/O46) -> 121.1364 | P47: =365/(P5/P46) -> 119.79463
A48: Average | B48: =AVERAGE(B47:K47) -> 122.85363 | C48: =AVERAGE(C47:L47) -> 122.93915 | D48: =AVERAGE(D47:M47) -> 121.5811 | E48: =AVERAGE(E47:N47) -> 121.1364 | F48: =AVERAGE(F47:O47) -> 119.79463
...

Sheet Ratio Analysis
B1: ="Ratio Analysis for "&'Data Sheet'!B1 -> Ratio Analysis for HINDUSTAN UNILEVER LTD
B2: ='Historical Financial Statement'!B2 -> Report Date | C2: ='Historical Financial Statement'!C2 -> 42825 | D2: ='Historical Financial Statement'!D2 -> 43190 | E2: ='Historical Financial Statement'!E2 -> 43555 | F2: ='Historical Financial Statement'!F2 -> 43921 | G2: ='Historical Financial Statement'!G2 -> 44286 | H2: ='Historical Financial Statement'!H2 -> 44651 | I2: ='Historical Financial Statement'!I2 -> 45016 | ... Q2: ='Historical Financial Statement'!Q2 -> 47937
B3: Profitability Ratios
B4: Gross Profit Margin | C4: ='Historical Financial Statement'!C9 -> 0.43653183 | D4: ='Historical Financial Statement'!D9 -> 0.45691528 | E4: ='Historical Financial Statement'!E9 -> 0.46431561 | F4: ='Historical Financial Statement'!F9 -> 0.48250612 | G4: ='Historical Financial Statement'!G9 -> 0.46140969 | H4: ='Historical Financial Statement'!H9 -> 0.4455492 | I4: ='Historical Financial Statement'!I9 -> 0.41356689 | J4: ='Historical Financial Statement'!J9 -> 0.45345549 | ... Q4: ='Historical Financial Statement'!Q9 -> 0.44632424
B5: EBITDA Margin | C5: ='Historical Financial Statement'!C14 -> 0.18962057 | D5: ='Historical Financial Statement'!D14 -> 0.21074584 | E5: ='Historical Financial Statement'!E14 -> 0.22595751 | F5: ='Historical Financial Statement'!F14 -> 0.24751837 | G5: ='Historical Financial Statement'!G14 -> 0.24619532 | H5: ='Historical Financial Statement'!H14 -> 0.24423261 | I5: ='Historical Financial Statement'!I14 -> 0.2304883 | J5: ='Historical Financial Statement'!J14 -> 0.2346657 | ... Q5: ='Historical Financial Statement'!Q14 -> 0.24069735
B6: EBIT Margin | C6: ='Historical Financial Statement'!C18 -> 0.17720288 | D6: ='Historical Financial Statement'!D18 -> 0.1969008 | E6: ='Historical Financial Statement'!E18 -> 0.21224885 | F6: ='Historical Financial Statement'!F18 -> 0.22333376 | G6: ='Historical Financial Statement'!G18 -> 0.22419341 | H6: ='Historical Financial Statement'!H18 -> 0.22421034 | I6: ='Historical Financial Statement'!I18 -> 0.21307318 | J6: ='Historical Financial Statement'!J18 -> 0.21652417 | ... Q6: ='Historical Financial Statement'!Q18 -> 0.22672268
B7: Net Profit Margin | C7: ='Historical Financial Statement'!C27 -> 0.14079649 | D7: ='Historical Financial Statement'!D27 -> 0.15168718 | E7: ='Historical Financial Statement'!E27 -> 0.15791126 | F7: ='Historical Financial Statement'!F27 -> 0.17372696 | G7: ='Historical Financial Statement'!G27 -> 0.17292808 | H7: ='Historical Financial Statement'!H27 -> 0.17225011 | I7: ='Historical Financial Statement'!I27 -> 0.16843636 | J7: ='Historical Financial Statement'!J27 -> 0.16725926 | ... Q7: ='Historical Financial Statement'!Q27 -> 0.20470813
B8: Return On Assests | C8: ='Historical Financial Statement'!C26/'Historical Financial Statement'!C61 -> 0.30438614 | D8: ='Historical Financial Statement'!D26/'Historical Financial Statement'!D61 -> 0.30538224 | E8: ='Historical Financial Statement'!E26/'Historical Financial Statement'!E61 -> 0.33786734 | F8: ='Historical Financial Statement'!F26/'Historical Financial Statement'!F61 -> 0.34374043 | G8: ='Historical Financial Statement'!G26/'Historical Financial Statement'!G61 -> 0.11677139 | H8: ='Historical Financial Statement'!H26/'Historical Financial Statement'!H61 -> 0.12644651 | I8: ='Historical Financial Statement'!I26/'Historical Financial Statement'!I61 -> 0.13869822 | J8: ='Historical Financial Statement'!J26/'Historical Financial Statement'!J61 -> 0.13122113 | ... Q8: ='Historical Financial Statement'!Q26/'Historical Financial Statement'!Q61 -> 0.22291617
B9: Return On Equity | C9: ='Historical Financial Statement'!C26/SUM('Historical Financial Statement'!C31:C32) -> 0.69183359 | D9: ='Historical Financial Statement'!D26/SUM('Historical Financial Statement'!D31:D32) -> 0.74021201 | E9: ='Historical Financial Statement'!E26/SUM('Historical Financial Statement'!E31:E32) -> 0.78809244 | F9: ='Historical Financial Statement'!F26/SUM('Historical Financial Statement'!F31:F32) -> 0.83899888 | G9: ='Historical Financial Statement'!G26/SUM('Historical Financial Statement'!G31:G32) -> 0.16768563 | H9: ='Historical Financial Statement'!H26/SUM('Historical Financial Statement'!H31:H32) -> 0.18084495 | I9: ='Historical Financial Statement'!I26/SUM('Historical Financial Statement'!I31:I32) -> 0.19836323 | J9: ='Historical Financial Statement'!J26/SUM('Historical Financial Statement'!J31:J32) -> 0.19841877 | ... Q9: ='Historical Financial Statement'!Q26/SUM('Historical Financial Statement'!Q31:Q32) -> 0.29886044
B11: Solvency Ratios
B12: D/E Ratio | C12: ='Historical Financial Statement'!C41/SUM('Historical Financial Statement'!C31:C32) -> 0 | D12: ='Historical Financial Statement'!D41/SUM('Historical Financial Statement'!D31:D32) -> 0 | E12: ='Historical Financial Statement'!E41/SUM('Historical Financial Statement'!E31:E32) -> 0 | F12: ='Historical Financial Statement'!F41/SUM('Historical Financial Statement'!F31:F32) -> 0 | G12: ='Historical Financial Statement'!G41/SUM('Historical Financial Statement'!G31:G32) -> 0.019880255 | H12: ='Historical Financial Statement'!H41/SUM('Historical Financial Statement'!H31:H32) -> 0.019913864 | I12: ='Historical Financial Statement'!I41/SUM('Historical Financial Statement'!I31:I32) -> 0.020688557 | J12: ='Historical Financial Statement'!J41/SUM('Historical Financial Statement'!J31:J32) -> 0.026955447 | ... Q12: ='Historical Financial Statement'!Q41/SUM('Historical Financial Statement'!Q31:Q32) -> 0.022819407
B13: Debt Ratio | C13: ='Historical Financial Statement'!C41/'Historical Financial Statement'!C61 -> 0 | D13: ='Historical Financial Statement'!D41/'Historical Financial Statement'!D61 -> 0 | E13: ='Historical Financial Statement'!E41/'Historical Financial Statement'!E61 -> 0 | F13: ='Historical Financial Statement'!F41/'Historical Financial Statement'!F61 -> 0 | G13: ='Historical Financial Statement'!G41/'Historical Financial Statement'!G61 -> 0.013844031 | H13: ='Historical Financial Statement'!H41/'Historical Financial Statement'!H61 -> 0.013923742 | I13: ='Historical Financial Statement'!I41/'Historical Financial Statement'!I61 -> 0.014465715 | J13: ='Historical Financial Statement'!J41/'Historical Financial Statement'!J61 -> 0.017826561 | ... Q13: ='Historical Financial Statement'!Q41/'Historical Financial Statement'!Q61 -> 0.017020703
B14: Interest Coverage Ratio | C14: ='Historical Financial Statement'!C17/'Historical Financial Statement'!C20 -> 256.86364 | D14: ='Historical Financial Statement'!D17/'Historical Financial Statement'!D20 -> 339.9 | E14: ='Historical Financial Statement'!E17/'Historical Financial Statement'!E20 -> 289.75 | F14: ='Historical Financial Statement'!F17/'Historical Financial Statement'!F20 -> 81.716981 | G14: ='Historical Financial Statement'!G17/'Historical Financial Statement'!G20 -> 95.481481 | H14: ='Historical Financial Statement'!H17/'Historical Financial Statement'!H20 -> 117.12245 | I14: ='Historical Financial Statement'!I17/'Historical Financial Statement'!I20 -> 124.77228 | J14: ='Historical Financial Statement'!J17/'Historical Financial Statement'!J20 -> 43.354305 | ... Q14: ='Historical Financial Statement'!Q17/'Historical Financial Statement'!Q20 -> 68.88523
B16: Efficency Ratios
B17: Assets Turnover Ratio | C17: ='Historical Financial Statement'!C5/'Historical Financial Statement'!C61 -> 2.1618873 | D17: ='Historical Financial Statement'!D5/'Historical Financial Statement'!D61 -> 2.0132369 | E17: ='Historical Financial Statement'!E5/'Historical Financial Statement'!E61 -> 2.1396026 | F17: ='Historical Financial Statement'!F5/'Historical Financial Statement'!F61 -> 1.9786246 | G17: ='Historical Financial Statement'!G5/'Historical Financial Statement'!G61 -> 0.67525985 | H17: ='Historical Financial Statement'!H5/'Historical Financial Statement'!H61 -> 0.73408664 | I17: ='Historical Financial Statement'!I5/'Historical Financial Statement'!I61 -> 0.82344588 | J17: ='Historical Financial Statement'!J5/'Historical Financial Statement'!J61 -> 0.78453734 | ... Q17: ='Historical Financial Statement'!Q5/'Historical Financial Statement'!Q61 -> 1.0889464
B18: Inventory Turnover Ratio | C18: ='Historical Financial Statement'!C7/'Historical Financial Statement'!C57 -> 7.607536 | D18: ='Historical Financial Statement'!D7/'Historical Financial Statement'!D57 -> 7.9482832 | E18: ='Historical Financial Statement'!E7/'Historical Financial Statement'!E57 -> 8.4541701 | F18: ='Historical Financial Statement'!F7/'Historical Financial Statement'!F57 -> 7.6141882 | G18: ='Historical Financial Statement'!G7/'Historical Financial Statement'!G57 -> 7.3227904 | H18: ='Historical Financial Statement'!H7/'Historical Financial Statement'!H57 -> 7.2966581 | I18: ='Historical Financial Statement'!I7/'Historical Financial Statement'!I57 -> 8.6043165 | J18: ='Historical Financial Statement'!J7/'Historical Financial Statement'!J57 -> 8.6697272 | ... Q18: ='Historical Financial Statement'!Q7/'Historical Financial Statement'!Q57 -> 7.919886
B19: Receivable Turnover Ratio | C19: ='Historical Financial Statement'!C5/'Historical Financial Statement'!C56 -> 34.364224 | D19: ='Historical Financial Statement'!D5/'Historical Financial Statement'!D56 -> 30.100262 | E19: ='Historical Financial Statement'!E5/'Historical Financial Statement'!E56 -> 22.847579 | F19: ='Historical Financial Statement'!F5/'Historical Financial Statement'!F56 -> 37.07935 | G19: ='Historical Financial Statement'!G5/'Historical Financial Statement'!G56 -> 27.910194 | H19: ='Historical Financial Statement'!H5/'Historical Financial Statement'!H56 -> 26.497412 | I19: ='Historical Financial Statement'!I5/'Historical Financial Statement'!I56 -> 21.624863 | J19: ='Historical Financial Statement'!J5/'Historical Financial Statement'!J56 -> 22.479182 | ... Q19: ='Historical Financial Statement'!Q5/'Historical Financial Statement'!Q56 -> 22.846473
B20: Payable Turnover Ratio | C20: ='Historical Financial Statement'!C7/'Historical Financial Statement'!C36 -> 2.9918415 | D20: ='Historical Financial Statement'!D7/'Historical Financial Statement'!D36 -> 2.6736062 | E20: ='Historical Financial Statement'!E7/'Historical Financial Statement'!E36 -> 2.896181 | F20: ='Historical Financial Statement'!F7/'Historical Financial Statement'!F36 -> 2.7126639 | G20: ='Historical Financial Statement'!G7/'Historical Financial Statement'!G36 -> 2.871566 | H20: ='Historical Financial Statement'!H7/'Historical Financial Statement'!H36 -> 3.2021661 | I20: ='Historical Financial Statement'!I7/'Historical Financial Statement'!I36 -> 3.6933234 | J20: ='Historical Financial Statement'!J7/'Historical Financial Statement'!J36 -> 3.2567008 | ... Q20: ='Historical Financial Statement'!Q7/'Historical Financial Statement'!Q36 -> 3.0468811
B21: Fixed Assets Turnover Ratio | C21: ='Historical Financial Statement'!C5/'Historical Financial Statement'!C49 -> 7.9249503 | D21: ='Historical Financial Statement'!D5/'Historical Financial Statement'!D49 -> 8.3353452 | E21: ='Historical Financial Statement'!E5/'Historical Financial Statement'!E49 -> 8.8012894 | F21: ='Historical Financial Statement'!F5/'Historical Financial Statement'!F49 -> 7.6710839 | G21: ='Historical Financial Statement'!G5/'Historical Financial Statement'!G49 -> 0.90140514 | H21: ='Historical Financial Statement'!H5/'Historical Financial Statement'!H49 -> 1.0031156 | I21: ='Historical Financial Statement'!I5/'Historical Financial Statement'!I49 -> 1.1505496 | J21: ='Historical Financial Statement'!J5/'Historical Financial Statement'!J49 -> 1.1544512 | ... Q21: ='Historical Financial Statement'!Q5/'Historical Financial Statement'!Q49 -> 1.4680242
B23: Liquidity Ratios
B24: Current Ratio | C24: ='Historical Financial Statement'!C59/'Historical Financial Statement'!C38 -> 0.81649111 | D24: ='Historical Financial Statement'!D59/'Historical Financial Statement'!D38 -> 0.97325976 | E24: ='Historical Financial Statement'!E59/'Historical Financial Statement'!E38 -> 1.0948094 | F24: ='Historical Financial Statement'!F59/'Historical Financial Statement'!F38 -> 1.1517278 | G24: ='Historical Financial Statement'!G59/'Historical Financial Statement'!G38 -> 1.0724771 | H24: ='Historical Financial Statement'!H59/'Historical Financial Statement'!H38 -> 1.0515763 | I24: ='Historical Financial Statement'!I59/'Historical Financial Statement'!I38 -> 1.1805424 | J24: ='Historical Financial Statement'!J59/'Historical Financial Statement'!J38 -> 1.340041 | ... Q24: ='Historical Financial Statement'!Q59/'Historical Financial Statement'!Q38 -> 0.28711999
B25: Quick Ratio | C25: =('Historical Financial Statement'!C59-'Historical Financial Statement'!C57)/'Historical Financial Statement'!C38 -> 0.42774852 | D25: =('Historical Financial Statement'!D59-'Historical Financial Statement'!D57)/'Historical Financial Statement'!D38 -> 0.63950198 | E25: =('Historical Financial Statement'!E59-'Historical Financial Statement'!E57)/'Historical Financial Statement'!E38 -> 0.7541145 | F25: =('Historical Financial Statement'!F59-'Historical Financial Statement'!F57)/'Historical Financial Statement'!F38 -> 0.80272739 | G25: =('Historical Financial Statement'!G59-'Historical Financial Statement'!G57)/'Historical Financial Statement'!G38 -> 0.68451835 | H25: =('Historical Financial Statement'!H59-'Historical Financial Statement'!H57)/'Historical Financial Statement'!H38 -> 0.61824663 | I25: =('Historical Financial Statement'!I59-'Historical Financial Statement'!I57)/'Historical Financial Statement'!I38 -> 0.75519679 | J25: =('Historical Financial Statement'!J59-'Historical Financial Statement'!J57)/'Historical Financial Statement'!J38 -> 0.96766631 | ... Q25: =('Historical Financial Statement'!Q59-'Historical Financial Statement'!Q57)/'Historical Financial Statement'!Q38 -> -0.094779333
B26: Cash Ratio | C26: ='Historical Financial Statement'!C58/'Historical Financial Statement'!C38 -> 0.27501646 | D26: ='Historical Financial Statement'!D58/'Historical Financial Statement'!D38 -> 0.47722128 | E26: ='Historical Financial Statement'!E58/'Historical Financial Statement'!E38 -> 0.51877901 | F26: ='Historical Financial Statement'!F58/'Historical Financial Statement'!F38 -> 0.66423938 | G26: ='Historical Financial Statement'!G58/'Historical Financial Statement'!G38 -> 0.49552752 | H26: ='Historical Financial Statement'!H58/'Historical Financial Statement'!H38 -> 0.40302997 | I26: ='Historical Financial Statement'!I58/'Historical Financial Statement'!I38 -> 0.46660336 | J26: ='Historical Financial Statement'!J58/'Historical Financial Statement'!J38 -> 0.70489401 | ... Q26: ='Historical Financial Statement'!Q58/'Historical Financial Statement'!Q38 -> -0.3338868
B28: Market Ratios
B29: Eairning Per Share | C29: ='Historical Financial Statement'!C26/'Data Sheet'!B93 -> 20.745738 | D29: ='Historical Financial Statement'!D26/'Data Sheet'!C93 -> 24.194964 | E29: ='Historical Financial Statement'!E26/'Data Sheet'!D93 -> 27.883771 | F29: ='Historical Financial Statement'!F26/'Data Sheet'!E93 -> 31.125277 | G29: ='Historical Financial Statement'!G26/'Data Sheet'!F93 -> 33.852571 | H29: ='Historical Financial Statement'!H26/'Data Sheet'!G93 -> 37.529792 | I29: ='Historical Financial Statement'!I26/'Data Sheet'!H93 -> 42.398706 | J29: ='Historical Financial Statement'!J26/'Data Sheet'!I93 -> 43.045625 | ... L29: ='Historical Financial Statement'!L26/'Data Sheet'!K93 -> 65.657984 | M29: =_xlfn.FORECAST.LINEAR(M$2,$C29:$L29,$C$2:$L$2) -> 59.343907 | N29: =_xlfn.FORECAST.LINEAR(N$2,$C29:$L29,$C$2:$L$2) -> 63.372869 | O29: =_xlfn.FORECAST.LINEAR(O$2,$C29:$L29,$C$2:$L$2) -> 67.401832 | P29: =_xlfn.FORECAST.LINEAR(P$2,$C29:$L29,$C$2:$L$2) -> 71.430794 | Q29: =_xlfn.FORECAST.LINEAR(Q$2,$C29:$L29,$C$2:$L$2) -> 75.459756
B30: P/E Ratio | C30: ='Data Sheet'!B90/'Ratio Analysis'!C29 -> 42.062134 | D30: ='Data Sheet'!C90/'Ratio Analysis'!D29 -> 52.742793 | E30: ='Data Sheet'!D90/'Ratio Analysis'!E29 -> 58.583539 | F30: ='Data Sheet'!E90/'Ratio Analysis'!F29 -> 70.67664 | G30: ='Data Sheet'!F90/'Ratio Analysis'!G29 -> 68.742785 | H30: ='Data Sheet'!G90/'Ratio Analysis'!H29 -> 52.243828 | I30: ='Data Sheet'!H90/'Ratio Analysis'!I29 -> 57.79516 | J30: ='Data Sheet'!I90/'Ratio Analysis'!J29 -> 50.345186 | ... L30: ='Data Sheet'!K90/'Ratio Analysis'!L29 -> 31.301601 | M30: =_xlfn.FORECAST.LINEAR(M$2,$C30:$L30,$C$2:$L$2) -> 45.613225 | N30: =_xlfn.FORECAST.LINEAR(N$2,$C30:$L30,$C$2:$L$2) -> 44.230575 | O30: =_xlfn.FORECAST.LINEAR(O$2,$C30:$L30,$C$2:$L$2) -> 42.847925 | P30: =_xlfn.FORECAST.LINEAR(P$2,$C30:$L30,$C$2:$L$2) -> 41.465275 | Q30: =_xlfn.FORECAST.LINEAR(Q$2,$C30:$L30,$C$2:$L$2) -> 40.082625
B31: Book Value Per Share | C31: =SUM('Historical Financial Statement'!C31:C32)/'Data Sheet'!B93 -> 29.986601 | D31: =SUM('Historical Financial Statement'!D31:D32)/'Data Sheet'!C93 -> 32.686533 | E31: =SUM('Historical Financial Statement'!E31:E32)/'Data Sheet'!D93 -> 35.381346 | F31: =SUM('Historical Financial Statement'!F31:F32)/'Data Sheet'!E93 -> 37.098115 | G31: =SUM('Historical Financial Statement'!G31:G32)/'Data Sheet'!F93 -> 201.88117 | H31: =SUM('Historical Financial Statement'!H31:H32)/'Data Sheet'!G93 -> 207.52469 | I31: =SUM('Historical Financial Statement'!I31:I32)/'Data Sheet'!H93 -> 213.74276 | J31: =SUM('Historical Financial Statement'!J31:J32)/'Data Sheet'!I93 -> 216.94331 | ... L31: =SUM('Historical Financial Statement'!L31:L32)/'Data Sheet'!K93 -> 209.49523 | M31: =_xlfn.FORECAST.LINEAR(M$2,$C31:$L31,$C$2:$L$2) -> 282.5149 | N31: =_xlfn.FORECAST.LINEAR(N$2,$C31:$L31,$C$2:$L$2) -> 308.52398 | O31: =_xlfn.FORECAST.LINEAR(O$2,$C31:$L31,$C$2:$L$2) -> 334.53306 | P31: =_xlfn.FORECAST.LINEAR(P$2,$C31:$L31,$C$2:$L$2) -> 360.54214 | Q31: =_xlfn.FORECAST.LINEAR(Q$2,$C31:$L31,$C$2:$L$2) -> 386.55122
B33: Operating Cycle Ratios (in Days)
B34: Inventory Days | C34: =365/C18 -> 47.978741 | D34: =365/D18 -> 45.921867 | E34: =365/E18 -> 43.17396 | F34: =365/F18 -> 47.936824 | G34: =365/G18 -> 49.844387 | H34: =365/H18 -> 50.0229 | I34: =365/I18 -> 42.420569 | J34: =365/J18 -> 42.100517 | ... L34: =365/L18 -> 46.005493 | M34: =Calculation!L71 -> 46.152487 | N34: =Calculation!M71 -> 45.969862 | O34: =Calculation!N71 -> 45.974661 | P34: =Calculation!O71 -> 46.254731 | Q34: =Calculation!P71 -> 46.086522
B35: Receivable Days | C35: =365/C19 -> 10.621511 | D35: =365/D19 -> 12.12614 | E35: =365/E19 -> 15.975434 | F35: =365/F19 -> 9.843754 | G35: =365/G19 -> 13.077659 | H35: =365/H19 -> 13.77493 | I35: =365/I19 -> 16.87872 | J35: =365/J19 -> 16.237246 | ... L35: =365/L19 -> 17.886325 | M35: =Calculation!L67 -> 14.752317 | N35: =Calculation!M67 -> 15.165397 | O35: =Calculation!N67 -> 15.469323 | P35: =Calculation!O67 -> 15.418712 | Q35: =Calculation!P67 -> 15.976208
B36: Payable Days | C36: =365/C20 -> 121.99844 | D36: =365/D20 -> 136.51973 | E36: =365/E20 -> 126.02803 | F36: =365/F20 -> 134.55408 | G36: =365/G20 -> 127.10834 | H36: =365/H20 -> 113.98534 | I36: =365/I20 -> 98.826981 | J36: =365/J20 -> 112.07661 | ... L36: =365/L20 -> 135.53934 | M36: =Calculation!L47 -> 122.85363 | N36: =Calculation!M47 -> 122.93915 | O36: =Calculation!N47 -> 121.5811 | P36: =Calculation!O47 -> 121.1364 | Q36: =Calculation!P47 -> 119.79463
B38: Cash Conversion Days | C38: =SUM(C34:C35)-C36 -> -63.398189 | D38: =SUM(D34:D35)-D36 -> -78.471726 | E38: =SUM(E34:E35)-E36 -> -66.878639 | F38: =SUM(F34:F35)-F36 -> -76.773505 | G38: =SUM(G34:G35)-G36 -> -64.186298 | H38: =SUM(H34:H35)-H36 -> -50.187513 | I38: =SUM(I34:I35)-I36 -> -39.527692 | J38: =SUM(J34:J35)-J36 -> -53.738851 | ... Q38: =SUM(Q34:Q35)-Q36 -> -57.731903
B40: Market Prospect Ratios
B41: Dividend Payout Ratio | C41: ='Data Sheet'!B31/'Data Sheet'!B30 -> 0.81781737 | D41: ='Data Sheet'!C31/'Data Sheet'!C30 -> 0.82489975 | E41: ='Data Sheet'!D31/'Data Sheet'!D30 -> 0.78727634 | F41: ='Data Sheet'!E31/'Data Sheet'!E30 -> 0.80142476 | G41: ='Data Sheet'!F31/'Data Sheet'!F30 -> 1.1965678 | H41: ='Data Sheet'!G31/'Data Sheet'!G30 -> 0.90610116 | I41: ='Data Sheet'!H31/'Data Sheet'!H30 -> 0.91999598 | J41: ='Data Sheet'!I31/'Data Sheet'!I30 -> 0.97587502 | ... L41: ='Data Sheet'!K31/'Data Sheet'!K30 -> 0.62455435 | M41: =_xlfn.FORECAST.LINEAR(M$2,C$41:L$41,$C$2:$L$2) -> 0.95866317 | N41: =_xlfn.FORECAST.LINEAR(N$2,D$41:M$41,$C$2:$L$2) -> 0.96622027 | O41: =_xlfn.FORECAST.LINEAR(O$2,E$41:N$41,$C$2:$L$2) -> 0.96236813 | P41: =_xlfn.FORECAST.LINEAR(P$2,F$41:O$41,$C$2:$L$2) -> 0.91766111 | Q41: =_xlfn.FORECAST.LINEAR(Q$2,G$41:P$41,$C$2:$L$2) -> 0.81699167
B42: Retention Ratio | C42: =1-C41 -> 0.18218263 | D42: =1-D41 -> 0.17510025 | E42: =1-E41 -> 0.21272366 | F42: =1-F41 -> 0.19857524 | G42: =1-G41 -> -0.19656776 | H42: =1-H41 -> 0.093898843 | I42: =1-I41 -> 0.080004015 | J42: =1-J41 -> 0.024124975 | ... Q42: =1-Q41 -> 0.18300833
B44: Sustainable Growth Rate | C44: =C42*C9 -> 0.12604006 | D44: =D42*D9 -> 0.12961131 | E44: =E42*E9 -> 0.16764591 | F44: =F42*F9 -> 0.16660441 | G44: =G42*G9 -> -0.032961589 | H44: =H42*H9 -> 0.016981132 | I44: =I42*I9 -> 0.015869855 | J44: =J42*J9 -> 0.0047868479 | ... Q44: =Q42*Q9 -> 0.054693951

Sheet DCF Model
B1: ="DCF Model for "&'Data Sheet'!B1 -> DCF Model for HINDUSTAN UNILEVER LTD
B2: ="WACC Calculation for "&'Data Sheet'!B1 -> WACC Calculation for HINDUSTAN UNILEVER LTD | E2: ="Discount Cash-Flow for "&'Data Sheet'!B1 -> Discount Cash-Flow for HINDUSTAN UNILEVER LTD
B3: Equity | C3: 426802 | F3: 1 | G3: 2 | H3: 3 | I3: 4 | J3: 5 | K3: 6 | L3: 7 | M3: 8 | N3: 9 | O3: 10
B4: Debt | C4: 1325 | E4: EBIT | F4: ='Historical Financial Statement'!C17 -> 5651 | G4: ='Historical Financial Statement'!D17 -> 6798 | H4: ='Historical Financial Statement'!E17 -> 8113 | I4: ='Historical Financial Statement'!F17 -> 8662 | J4: ='Historical Financial Statement'!G17 -> 10312 | K4: ='Historical Financial Statement'!H17 -> 11478 | L4: ='Historical Financial Statement'!I17 -> 12602 | M4: ='Historical Financial Statement'!J17 -> 13093 | ... O4: ='Historical Financial Statement'!L17 -> 13278
B5: Weightage of Equity | C5: =C3/SUM(C3:C4) -> 0.99690512 | E5: Tax Rate | F5: =$C7 -> 0.16552172 | G5: =$C7 -> 0.16552172 | H5: =$C7 -> 0.16552172 | I5: =$C7 -> 0.16552172 | J5: =$C7 -> 0.16552172 | K5: =$C7 -> 0.16552172 | L5: =$C7 -> 0.16552172 | M5: =$C7 -> 0.16552172 | ... O5: =$C7 -> 0.16552172
B6: Weightage of Debt | C6: =C4/SUM(C3:C4) -> 0.0030948761 | E6: Depreciation | F6: ='Historical Financial Statement'!C16 -> 396 | G6: ='Historical Financial Statement'!D16 -> 478 | H6: ='Historical Financial Statement'!E16 -> 524 | I6: ='Historical Financial Statement'!F16 -> 938 | J6: ='Historical Financial Statement'!G16 -> 1012 | K6: ='Historical Financial Statement'!H16 -> 1025 | L6: ='Historical Financial Statement'!I16 -> 1030 | M6: ='Historical Financial Statement'!J16 -> 1097 | ... O6: ='Historical Financial Statement'!L16 -> 1186
B7: Tax | C7: ='Historical Financial Statement'!L25/'Historical Financial Statement'!L22 -> 0.16552172 | E7: CapEx | F7: ='Historical Financial Statement'!C78 -> -1024 | G7: ='Historical Financial Statement'!D78 -> -853 | H7: ='Historical Financial Statement'!E78 -> -728 | I7: ='Historical Financial Statement'!F78 -> -765 | J7: ='Historical Financial Statement'!G78 -> -4051 | K7: ='Historical Financial Statement'!H78 -> -919 | L7: ='Historical Financial Statement'!I78 -> -1041 | M7: ='Historical Financial Statement'!J78 -> -1318 | ... O7: ='Historical Financial Statement'!L78 -> -1274
